Workbook

Sheet Tổng quan
A1: VIVOIRE vs FRACILE — bảng so sánh chi tiết
A2: Vivoire: đọc từ trang chủ vivoire.app ngày 09/09/2026 — CHƯA đọc lại. Không có tài khoản nên không kiểm được bên trong sản phẩm.
A3: FRACILE: đo từ mã nguồn và database production ngày 22/09/2026.
A4: Mọi con số ở sheet này TÍNH từ sheet « So sánh chi tiết » — sửa điểm ở đó thì ở đây tự đổi theo.
A6: Nhóm | B6: Số mục | C6: So được | D6: Điểm TB Vivoire | E6: Điểm TB FRACILE | F6: Chênh lệch | G6: Bên nào hơn
A7: A. Chấm bài | B7: =COUNTIF('So sánh chi tiết'!$A$2:$A$83,$A7) -> 9 | C7: =SUMPRODUCT(('So sánh chi tiết'!$A$2:$A$83=$A7)*('So sánh chi tiết'!$D$2:$D$83<>"")*('So sánh chi tiết'!$F$2:$F$83<>"")) -> 9 | D7: =IFERROR(SUMPRODUCT(('So sánh chi tiết'!$A$2:$A$83=$A7)*('So sánh chi tiết'!$D$2:$D$83<>"")*('So sánh chi tiết'!$F$2:$F$83<>"")*'So sánh chi tiết'!$D$2:$D$83)/SUMPRODUCT(('So sánh chi tiết'!$A$2:$A$83=$A7)*('So sánh chi tiết'!$D$2:$D$83<>"")*('So sánh chi tiết'!$F$2:$F$83<>"")),"") -> 1.1111111 | E7: =IFERROR(SUMPRODUCT(('So sánh chi tiết'!$A$2:$A$83=$A7)*('So sánh chi tiết'!$D$2:$D$83<>"")*('So sánh chi tiết'!$F$2:$F$83<>"")*'So sánh chi tiết'!$F$2:$F$83)/SUMPRODUCT(('So sánh chi tiết'!$A$2:$A$83=$A7)*('So sánh chi tiết'!$D$2:$D$83<>"")*('So sánh chi tiết'!$F$2:$F$83<>"")),"") -> 1.5555556 | F7: =IFERROR(E7-D7,"") -> 0.44444444 | G7: =IF(OR(C7<3,F7=""),"quá ít mục",IF(F7>0.25,"FRACILE",IF(F7<-0.25,"Vivoire","ngang nhau"))) -> FRACILE
A8: B. Mô phỏng phòng thi | B8: =COUNTIF('So sánh chi tiết'!$A$2:$A$83,$A8) -> 11 | C8: =SUMPRODUCT(('So sánh chi tiết'!$A$2:$A$83=$A8)*('So sánh chi tiết'!$D$2:$D$83<>"")*('So sánh chi tiết'!$F$2:$F$83<>"")) -> 11 | D8: =IFERROR(SUMPRODUCT(('So sánh chi tiết'!$A$2:$A$83=$A8)*('So sánh chi tiết'!$D$2:$D$83<>"")*('So sánh chi tiết'!$F$2:$F$83<>"")*'So sánh chi tiết'!$D$2:$D$83)/SUMPRODUCT(('So sánh chi tiết'!$A$2:$A$83=$A8)*('So sánh chi tiết'!$D$2:$D$83<>"")*('So sánh chi tiết'!$F$2:$F$83<>"")),"") -> 0.18181818 | E8: =IFERROR(SUMPRODUCT(('So sánh chi tiết'!$A$2:$A$83=$A8)*('So sánh chi tiết'!$D$2:$D$83<>"")*('So sánh chi tiết'!$F$2:$F$83<>"")*'So sánh chi tiết'!$F$2:$F$83)/SUMPRODUCT(('So sánh chi tiết'!$A$2:$A$83=$A8)*('So sánh chi tiết'!$D$2:$D$83<>"")*('So sánh chi tiết'!$F$2:$F$83<>"")),"") -> 2 | F8: =IFERROR(E8-D8,"") -> 1.8181818 | G8: =IF(OR(C8<3,F8=""),"quá ít mục",IF(F8>0.25,"FRACILE",IF(F8<-0.25,"Vivoire","ngang nhau"))) -> FRACILE
A9: C. Thư viện nội dung | B9: =COUNTIF('So sánh chi tiết'!$A$2:$A$83,$A9) -> 9 | C9: =SUMPRODUCT(('So sánh chi tiết'!$A$2:$A$83=$A9)*('So sánh chi tiết'!$D$2:$D$83<>"")*('So sánh chi tiết'!$F$2:$F$83<>"")) -> 8 | D9: =IFERROR(SUMPRODUCT(('So sánh chi tiết'!$A$2:$A$83=$A9)*('So sánh chi tiết'!$D$2:$D$83<>"")*('So sánh chi tiết'!$F$2:$F$83<>"")*'So sánh chi tiết'!$D$2:$D$83)/SUMPRODUCT(('So sánh chi tiết'!$A$2:$A$83=$A9)*('So sánh chi tiết'!$D$2:$D$83<>"")*('So sánh chi tiết'!$F$2:$F$83<>"")),"") -> 1.5 | E9: =IFERROR(SUMPRODUCT(('So sánh chi tiết'!$A$2:$A$83=$A9)*('So sánh chi tiết'!$D$2:$D$83<>"")*('So sánh chi tiết'!$F$2:$F$83<>"")*'So sánh chi tiết'!$F$2:$F$83)/SUMPRODUCT(('So sánh chi tiết'!$A$2:$A$83=$A9)*('So sánh chi tiết'!$D$2:$D$83<>"")*('So sánh chi tiết'!$F$2:$F$83<>"")),"") -> 1.625 | F9: =IFERROR(E9-D9,"") -> 0.125 | G9: =IF(OR(C9<3,F9=""),"quá ít mục",IF(F9>0.25,"FRACILE",IF(F9<-0.25,"Vivoire","ngang nhau"))) -> ngang nhau
A10: D. Công cụ học tập | B10: =COUNTIF('So sánh chi tiết'!$A$2:$A$83,$A10) -> 25 | C10: =SUMPRODUCT(('So sánh chi tiết'!$A$2:$A$83=$A10)*('So sánh chi tiết'!$D$2:$D$83<>"")*('So sánh chi tiết'!$F$2:$F$83<>"")) -> 23 | D10: =IFERROR(SUMPRODUCT(('So sánh chi tiết'!$A$2:$A$83=$A10)*('So sánh chi tiết'!$D$2:$D$83<>"")*('So sánh chi tiết'!$F$2:$F$83<>"")*'So sánh chi tiết'!$D$2:$D$83)/SUMPRODUCT(('So sánh chi tiết'!$A$2:$A$83=$A10)*('So sánh chi tiết'!$D$2:$D$83<>"")*('So sánh chi tiết'!$F$2:$F$83<>"")),"") -> 0.52173913 | E10: =IFERROR(SUMPRODUCT(('So sánh chi tiết'!$A$2:$A$83=$A10)*('So sánh chi tiết'!$D$2:$D$83<>"")*('So sánh chi tiết'!$F$2:$F$83<>"")*'So sánh chi tiết'!$F$2:$F$83)/SUMPRODUCT(('So sánh chi tiết'!$A$2:$A$83=$A10)*('So sánh chi tiết'!$D$2:$D$83<>"")*('So sánh chi tiết'!$F$2:$F$83<>"")),"") -> 1.9565217 | F10: =IFERROR(E10-D10,"") -> 1.4347826 | G10: =IF(OR(C10<3,F10=""),"quá ít mục",IF(F10>0.25,"FRACILE",IF(F10<-0.25,"Vivoire","ngang nhau"))) -> FRACILE
A11: E. Tài khoản giáo viên | B11: =COUNTIF('So sánh chi tiết'!$A$2:$A$83,$A11) -> 16 | C11: =SUMPRODUCT(('So sánh chi tiết'!$A$2:$A$83=$A11)*('So sánh chi tiết'!$D$2:$D$83<>"")*('So sánh chi tiết'!$F$2:$F$83<>"")) -> 15 | D11: =IFERROR(SUMPRODUCT(('So sánh chi tiết'!$A$2:$A$83=$A11)*('So sánh chi tiết'!$D$2:$D$83<>"")*('So sánh chi tiết'!$F$2:$F$83<>"")*'So sánh chi tiết'!$D$2:$D$83)/SUMPRODUCT(('So sánh chi tiết'!$A$2:$A$83=$A11)*('So sánh chi tiết'!$D$2:$D$83<>"")*('So sánh chi tiết'!$F$2:$F$83<>"")),"") -> 0.53333333 | E11: =IFERROR(SUMPRODUCT(('So sánh chi tiết'!$A$2:$A$83=$A11)*('So sánh chi tiết'!$D$2:$D$83<>"")*('So sánh chi tiết'!$F$2:$F$83<>"")*'So sánh chi tiết'!$F$2:$F$83)/SUMPRODUCT(('So sánh chi tiết'!$A$2:$A$83=$A11)*('So sánh chi tiết'!$D$2:$D$83<>"")*('So sánh chi tiết'!$F$2:$F$83<>"")),"") -> 1.6666667 | F11: =IFERROR(E11-D11,"") -> 1.1333333 | G11: =IF(OR(C11<3,F11=""),"quá ít mục",IF(F11>0.25,"FRACILE",IF(F11<-0.25,"Vivoire","ngang nhau"))) -> FRACILE
A12: F. Nền tảng & phân phối | B12: =COUNTIF('So sánh chi tiết'!$A$2:$A$83,$A12) -> 4 | C12: =SUMPRODUCT(('So sánh chi tiết'!$A$2:$A$83=$A12)*('So sánh chi tiết'!$D$2:$D$83<>"")*('So sánh chi tiết'!$F$2:$F$83<>"")) -> 3 | D12: =IFERROR(SUMPRODUCT(('So sánh chi tiết'!$A$2:$A$83=$A12)*('So sánh chi tiết'!$D$2:$D$83<>"")*('So sánh chi tiết'!$F$2:$F$83<>"")*'So sánh chi tiết'!$D$2:$D$83)/SUMPRODUCT(('So sánh chi tiết'!$A$2:$A$83=$A12)*('So sánh chi tiết'!$D$2:$D$83<>"")*('So sánh chi tiết'!$F$2:$F$83<>"")),"") -> 1.6666667 | E12: =IFERROR(SUMPRODUCT(('So sánh chi tiết'!$A$2:$A$83=$A12)*('So sánh chi tiết'!$D$2:$D$83<>"")*('So sánh chi tiết'!$F$2:$F$83<>"")*'So sánh chi tiết'!$F$2:$F$83)/SUMPRODUCT(('So sánh chi tiết'!$A$2:$A$83=$A12)*('So sánh chi tiết'!$D$2:$D$83<>"")*('So sánh chi tiết'!$F$2:$F$83<>"")),"") -> 1.6666667 | F12: =IFERROR(E12-D12,"") -> 0 | G12: =IF(OR(C12<3,F12=""),"quá ít mục",IF(F12>0.25,"FRACILE",IF(F12<-0.25,"Vivoire","ngang nhau"))) -> ngang nhau
A13: G. Lòng tin & pháp lý | B13: =COUNTIF('So sánh chi tiết'!$A$2:$A$83,$A13) -> 8 | C13: =SUMPRODUCT(('So sánh chi tiết'!$A$2:$A$83=$A13)*('So sánh chi tiết'!$D$2:$D$83<>"")*('So sánh chi tiết'!$F$2:$F$83<>"")) -> 7 | D13: =IFERROR(SUMPRODUCT(('So sánh chi tiết'!$A$2:$A$83=$A13)*('So sánh chi tiết'!$D$2:$D$83<>"")*('So sánh chi tiết'!$F$2:$F$83<>"")*'So sánh chi tiết'!$D$2:$D$83)/SUMPRODUCT(('So sánh chi tiết'!$A$2:$A$83=$A13)*('So sánh chi tiết'!$D$2:$D$83<>"")*('So sánh chi tiết'!$F$2:$F$83<>"")),"") -> 1.2857143 | E13: =IFERROR(SUMPRODUCT(('So sánh chi tiết'!$A$2:$A$83=$A13)*('So sánh chi tiết'!$D$2:$D$83<>"")*('So sánh chi tiết'!$F$2:$F$83<>"")*'So sánh chi tiết'!$F$2:$F$83)/SUMPRODUCT(('So sánh chi tiết'!$A$2:$A$83=$A13)*('So sánh chi tiết'!$D$2:$D$83<>"")*('So sánh chi tiết'!$F$2:$F$83<>"")),"") -> 1.5714286 | F13: =IFERROR(E13-D13,"") -> 0.28571429 | G13: =IF(OR(C13<3,F13=""),"quá ít mục",IF(F13>0.25,"FRACILE",IF(F13<-0.25,"Vivoire","ngang nhau"))) -> FRACILE
A14: TOÀN BỘ | B14: =SUM(B7:B13) -> 82 | C14: =SUM(C7:C13) -> 76 | D14: =IFERROR(SUMPRODUCT(('So sánh chi tiết'!$D$2:$D$83<>"")*('So sánh chi tiết'!$F$2:$F$83<>"")*'So sánh chi tiết'!$D$2:$D$83)/SUMPRODUCT(('So sánh chi tiết'!$D$2:$D$83<>"")*('So sánh chi tiết'!$F$2:$F$83<>"")),"") -> 0.76315789 | E14: =IFERROR(SUMPRODUCT(('So sánh chi tiết'!$D$2:$D$83<>"")*('So sánh chi tiết'!$F$2:$F$83<>"")*'So sánh chi tiết'!$F$2:$F$83)/SUMPRODUCT(('So sánh chi tiết'!$D$2:$D$83<>"")*('So sánh chi tiết'!$F$2:$F$83<>"")),"") -> 1.7763158 | F14: =E14-D14 -> 1.0131579 | G14: =IF(F14>0.25,"FRACILE",IF(F14<-0.25,"Vivoire","ngang nhau")) -> FRACILE
A16: ĐỪNG ĐỌC DÒNG « TOÀN BỘ » NHƯ MỘT TỶ SỐ TRẬN ĐẤU — PHÉP CHỌN MỤC NGHIÊNG SẴN VỀ VIVOIRE.
A17: Hai cột « Điểm TB » chỉ tính trên những mục CẢ HAI bên đều có điểm — cột « So được » cho biết đó là bao nhiêu mục trong tổng số. Mọi mục « không thấy nêu » của Vivoire bị BỎ RA khỏi phép tính chứ không bị cho 0 điểm: tôi không có tài khoản Vivoire, và « không nêu » không phải là « không có ». Đổi lại, 19 mục FRACILE mạnh mà Vivoire không nêu (đồng hồ chạy khi đóng tab, 2 lượt nghe đếm ở máy chủ, thang chấm tự soạn…) cũng không được cộng vào đây. Bảng này đo NƠI HAI BÊN GẶP NHAU, không đo tổng giá trị hai sản phẩm. Và chỗ hai bên gặp nhau CHÍNH LÀ mặt hàng Vivoire đem đi bán: 30 mục so được đều là thứ họ đưa lên trang chủ. Nên trung bình nghiêng về họ theo đúng cách một bảng so sánh dựng từ trang bán hàng của đối thủ sẽ nghiêng. Đọc cột « So được » trước cột « Điểm TB »: nhóm nào dưới 3 mục thì cột cuối ghi « quá ít mục » và không kết luận gì.
A20: THANG ĐIỂM
A21: 0 | B21: Không có
A22: 1 | B22: Có nhưng hạn chế, hoặc đã dựng mà chưa chạy được đầu-cuối
A23: 2 | B23: Có và làm tốt
A24: (trống) | B24: Chưa kiểm chứng được — KHÔNG tính vào trung bình
A27: ĐÃ ĐỔI GÌ SO VỚI BẢN 09/09 — bản này đo 08/10/2026
A28: Chấm PE bằng AI | B28: Đã dựng (Edge Function cham-pe, 38 ca kiểm) nhưng CHƯA BẬT vì thiếu khoá API. Điểm 0 → 1: có mà chưa chạy được đầu-cuối.
A29: Flashcard đổi mô hình | B29: Thẻ SM-2 sinh từ lỗi sai đã gỡ; nay là bộ do giáo viên soạn, đã chạy thật với tài khoản học sinh. Điểm cơ chế 2 → 1: mất lịch ôn ngắt quãng — đúng chỗ Vivoire mạnh.
A30: FAQ + Điều khoản | B30: Có từ 21/09. Điểm 0 → 1, chưa lên 2: cả hai chưa có email liên hệ, Điều khoản chưa qua luật sư.
A31: Chính sách bảo mật | B31: Dựng rồi gỡ cùng ngày theo quyết định chủ dự án. Vẫn 0.
A32: 23/09 — dọn và sửa đáp án phía học sinh | B32: Sửa lỗi đáp án rỗng với học sinh (tô màu, điểm, điền từ, bảng, sắp xếp); 4 câu sắp xếp mang đáp án bị xáo, đã ghi lại. Gỡ /professeur/oral, xoá hai tài khoản thử, điền email liên hệ.
A33: 23/09 — cả hai đường ghi của giáo viên đã thử xong | B33: Lưu lời giải: 207→209. Đặt neo: lần đầu (tab cũ) không ghi gì, sau Ctrl+F5 ngay tại trang đó thì ghi đúng. Mỗi tab giữ riêng bản mã của nó.
A34: 23/09 — tìm ra nguyên nhân lỗi cũ | B34: Phép thử đối chứng trên lưu lời giải: không tải lại trang → dòng xanh, database không đổi; Ctrl+F5 rồi viết hai lần → 207 lên 209. Nguyên nhân của cả ba lỗi 'báo lưu mà không lưu' là TAB CHẠY BẢN JS CŨ, không phải máy chủ.
A35: 22/09 — lịch ôn lưu được | B35: Tài khoản thật bấm Tốt nhưng database không đổi; thêm hàm chấm có biên nhận (091), sau Ctrl+F5 thì lưu được. Nguyên nhân gốc chưa chứng minh — nghi tab chạy bản JS cũ. Bốn bộ Flashcard đã công khai.
A36: Làm tiếp cùng ngày | B36: Neo 1→2: 7 câu có neo thật. Flashcard cơ chế 1→2: có lại lịch ôn SM-2. Ba bộ nháp cho Đọc/Viết/Nói. Và SỬA LẠI một con số: « 8 bài tự luận học sinh đang chờ » — 7 bài là tài khoản thử của chủ dự án.
A37: 24/09 — hai lỗi mất dữ liệu khi LƯU BÀI | B37: Lưu bài xoá rồi chèn lại câu hỏi, nên (1) xoá sạch neo — 7 neo mất, đã khôi phục; (2) xoá lịch sử trả lời của học sinh qua ON DELETE CASCADE — answers còn 57 thay vì 127, KHÔNG khôi phục được. Cả hai đã sửa. Câu hỏi 372→353 và lời giải 209→188 chưa rõ nguyên nhân.
A38: 24/09 — giao diện | B38: Khách chưa đăng nhập vào thẳng trang giới thiệu. Gỡ khối « Lớp của bạn » ở thanh bên. Màn Thống kê dựng lại bằng số liệu thật.
A39: 25/09 — trang giới thiệu | B39: Nội dung mới do chủ dự án viết (5 chỗ chỉnh cho khớp sản phẩm: bỏ DALF, bỏ « chấm chữa theo barem », 'tự đối chiếu', 'phần lớn câu có lời giải', câu đồng ý không nhắc chính sách chưa có). Ảnh màn hình + ảnh đại diện thật, chân trang xanh, form « Gửi câu hỏi » gửi thật. Điểm « Xem đăng ký tư vấn » 1 → 2.
... A72: Số liệu trôi | B72: 33 bài (từ 34), 372 câu (từ 373), 9 tài khoản (từ 7). Không phải lỗi — thư viện và người dùng thay đổi; bảng này là ảnh chụp của một ngày.

Sheet So sánh chi tiết
A1: Nhóm | B1: Mục so sánh | C1: Vivoire | D1: Điểm Vivoire | E1: FRACILE | F1: Điểm FRACILE | G1: Ai hơn | H1: Trạng thái FRACILE | I1: Bằng chứng / nguồn đo
A2: A. Chấm bài | B2: Trắc nghiệm / điền từ / chia động từ | C2: « Đề chuẩn cấu trúc, chấm ngay » | D2: 2 | E2: Chấm ở MÁY CHỦ; đáp án không cấp SELECT cho trình duyệt | F2: 2 | G2: =IF(OR(D2="",F2=""),"chưa rõ",IF(F2>D2,"FRACILE",IF(D2>F2,"Vivoire","hoà"))) -> hoà | H2: Đang chạy | I2: Edge Function `grade` + migration 022 (answer_key khoá khỏi anon/authenticated)
A3: A. Chấm bài | B3: Bài viết (PE) — tự chấm theo thang | C3: KHÔNG CÓ (chủ dự án xác nhận 14/10) | D3: 0 | E3: Grille DELF CHÍNH THỨC, 6 tiêu chí, A1–B2; đối chiếu bài mình theo từng tiêu chí. 18/10: trang công khai /grille-delf giải thích grille bài Viết và bài Nói A1–C1 bằng tiếng Việt, đọc thẳng thang đang dùng để chấm | F3: 2 | G3: =IF(OR(D3="",F3=""),"chưa rõ",IF(F3>D3,"FRACILE",IF(D3>F3,"Vivoire","hoà"))) -> FRACILE | H3: Đang chạy | I3: PESelfEvaluation.jsx + shared/grilleRubric.js; check:grille 59 ca, check:bareme 457 ca
A4: A. Chấm bài | B4: Bài viết (PE) — AI chấm | C4: AI chấm ngữ pháp và cách diễn đạt | D4: 2 | E4: Làm lại 08/10: AI đóng vai giám khảo DELF, chấm theo grille + MỐC ĐIỂM của đúng trình độ; phiếu nhận xét có cấu trúc (điểm từng tiêu chí, điểm mạnh, cần cải thiện, trích dẫn, 3 ưu tiên sửa, câu viết lại). Thi thử: AI tự chấm khi mở Kết quả thi. 3 lượt AI/ngày (giờ VN), VIP không giới hạn. 18/10: hết lượt dùng thử thì hiện cửa sổ chung (hết gì, khi nào có lại, quyền lợi VIP, nút đăng ký); Bài viết mẫu VIP đánh dấu chỗ sửa ngay trong bài | F4: 2 | G4: =IF(OR(D4="",F4=""),"chưa rõ",IF(F4>D4,"FRACILE",IF(D4>F4,"Vivoire","hoà"))) -> hoà | H4: Đang chạy — phiếu kiểu mới chưa chạy đầu-cuối với AI thật | I4: cham-pe (chinhThuc + prompt mới), _shared/goiYPE.js mở rộng, NhanXetAI.jsx; check:champe 38 ca
A5: A. Chấm bài | B5: Bài nói (PO) — ghi âm và nghe lại | C5: Có, kèm phản hồi AI | D5: 2 | E5: Ghi âm + tự nghe lại; CỐ Ý không cho điểm (DELF chấm nói bằng đối thoại) | F5: 1 | G5: =IF(OR(D5="",F5=""),"chưa rõ",IF(F5>D5,"FRACILE",IF(D5>F5,"Vivoire","hoà"))) -> Vivoire | H5: Đang chạy | I5: migration 057/058; bucket `bai-noi` private, đường dẫn mang phân quyền theo user_id
A6: A. Chấm bài | B6: Bài nói (PO) — AI nhận xét | C6: Phát âm 82% · Trôi chảy 76% · Từ vựng B1 | D6: 2 | E6: Nút « AI nhận xét » cạnh bản ghi: chép lời + góp ý ngữ pháp, từ vựng, nối ý bằng tiếng Việt. CỐ Ý không cho điểm phần trăm (quy tắc 1). 6 lượt/24 giờ | F6: 1 | G6: =IF(OR(D6="",F6=""),"chưa rõ",IF(F6>D6,"FRACILE",IF(D6>F6,"Vivoire","hoà"))) -> Vivoire | H6: Đã dựng 27/09 — chưa chạy đầu-cuối (kho bai-noi 0 file) | I6: migration 107, Edge Function nhan-xet-noi (gpt-transcribe → gpt-6-luna)
A7: A. Chấm bài | B7: Giáo viên chấm tay | C7: Có — nằm trong màn lớp học của giáo viên | D7: 2 | E7: ĐÃ GỠ HẲN 09/09: route, mục menu, màn hình và nhãn i18n đều đi | F7: 0 | G7: =IF(OR(D7="",F7=""),"chưa rõ",IF(F7>D7,"FRACILE",IF(D7>F7,"Vivoire","hoà"))) -> Vivoire | H7: Đã gỡ — có chủ đích | I7: commit « Gỡ /professeur/copies ». PEGrading.jsx xoá; check:nav 94 đạt
A8: A. Chấm bài | B8: Lời giải thích cho câu làm sai | C8: KHÔNG CÓ (chủ dự án xác nhận 14/10) | D8: 0 | E8: 704/881 câu có lời giải. Thêm 09/10: đủ 111/111 bài luyện tập có « Từ vựng » + « Giải thích » (AI soạn, không lộ đáp án, không dấu gạch dài); « Đề và đáp án » mở cho học sinh SAU khi đã nộp bài. 23/10: « Giải thích và mẹo » của 68 bài luyện tập viết lại NGẮN (3 ý, mỗi ý một câu, trung bình 247 ký tự thay vì ~1.100); « Từ vựng của bài » thành thẻ từ có giống đực/cái, nút nghe, nút ghi sổ từ | F8: 2 | G8: =IF(OR(D8="",F8=""),"chưa rõ",IF(F8>D8,"FRACILE",IF(D8>F8,"Vivoire","hoà"))) -> FRACILE | H8: Đang chạy — nội dung AI soạn, giáo viên sửa được | I8: Edge Function soan-tai-lieu; migration 126 (corrige_bai)
A9: A. Chấm bài | B9: Neo đáp án vào ngữ liệu (chỉ ra CHỖ chứa câu trả lời) | C9: Không có | D9: 0 | E9: 22 câu trên 2 bài đọc có neo (7 câu « L'impact des locations saisonnières » + 15 câu « Dans le Gard… »), kèm 17 bẫy. 24/09: lưu bài không còn xoá neo | F9: 2 | G9: =IF(OR(D9="",F9=""),"chưa rõ",IF(F9>D9,"FRACILE",IF(D9>F9,"Vivoire","hoà"))) -> FRACILE | H9: Đang chạy — có dữ liệu | I9: Mỗi đoạn trích kiểm bằng kiemNeo() trên văn bản thật trước khi ghi; claim giả: học sinh đã làm đọc được 7 neo, chưa làm đọc được 0
A10: B. Mô phỏng phòng thi | B10: Đề thi thử đúng cấu trúc DELF | C10: Đề thi thử DELF A1–B2 « đúng cấu trúc » (FAQ 10/10); viết có AI chấm, nói luyện riêng qua bài phát âm. Không thấy DALF C1/C2 | D10: 2 | E10: 13 đề đã phát hành (A1 ×2 · A2 ×3 · B1 ×3 · B2 ×3 · C1 ×2), đủ 4 phần. B2 Đề 2 (11/10) soạn theo khuôn ba đề mẫu « tout public » chủ dự án gửi, phần đọc và nói dùng ba bài báo The Conversation THẬT (rút gọn, ghi « D'après »). Từ 12–13/10: phần nói ĐƯỢC CHẤM /25 (thi nói → tổng /100, bỏ nói → /75, ngưỡng đạt tỉ lệ 50 %), bốc thăm đề nói + thời gian chuẩn bị như thi thật, giao diện trình bày như tờ đề thật, câu Vrai/Faux có ô chép câu chứng minh. Từ 13/10: bài thi thử ở KHO RIÊNG (58 bài), không lẫn vào thư viện luyện tập (68 bài; 6 bài thư viện gốc từng dùng trong đề được nhân bản lại cho thư viện); phần nghe không hiện ảnh; chuyển bài trong phần nghe không làm mất bài đang nghe. 14/10: thêm 5 đề (A1 Đề 2, A2 Đề 3, B1 Đề 3, B2 Đề 3, C1 Đề 2), bài đọc B1–C1 và tài liệu nói B2–C1 lấy từ bài báo thật The Conversation; giấy nháp cho Nghe/Đọc/Viết; bút tô sáng trên bài đọc. 15/10: 3 đề DELF B2 làm lại theo FORMAT MỚI (khuôn đề TP68): Nghe 3 bài (9 + 9 + 7 đ, bài 3 gồm ba tài liệu ngắn nghe 1 lượt, tiêu đề DOCUMENT 1/2/3), Đọc 3 bài (9 + 9 + 7 đ, bài 3 ghép ý kiến diễn đàn), điểm riêng từng câu 0,5 đến 2 đ; đề cũ ẩn, không xoá. 19/10: 21 đề đang phát hành (A1 3, A2 3, B1 6, B2 6, DALF C1 3); A1, A2 đều là đề thường, B1, B2, C1 ngoài Đề 1 dành cho VIP. Đề mới B1, B2 Đề 4 đến 6 chủ đề nghị luận xã hội 2026 (mạng xã hội dưới 15 tuổi, sức khỏe tâm thần, mùa hè 2026, nhà ở, làm việc từ xa), bài đọc viết lại từ báo uy tín có ghi nguồn; A1 Đề 3, C1 Đề 3 nội dung do FRACILE soạn | F10: 2 | G10: =IF(OR(D10="",F10=""),"chưa rõ",IF(F10>D10,"FRACILE",IF(D10>F10,"Vivoire","hoà"))) -> hoà | H10: Đang chạy — phần nói chấm điểm và bốc thăm chưa ai thi thật | I10: ExamMode.jsx, BocThamNoi.jsx, examPaper.js (nguongTong); migration 135–137; check:exam 118 ca; migration 140 (store 'exam'), tab « Bài thi thử » cho giáo viên; lô 18 (scripts/nhap/lo18_*), GiayNhap.jsx, VanBanToSang.jsx
A11: B. Mô phỏng phòng thi | B11: Nghe hiểu giới hạn 2 lượt phát | C11: KHÔNG CÓ (chủ dự án xác nhận 14/10) | D11: 0 | E11: Đếm ở MÁY CHỦ. Từ 08/10 MỌI đề thi thử (21 bài nghe) dùng « nghe kiểu phòng thi »: 30 s đọc câu hỏi, lượt 1, nghỉ 30 s, lượt 2, 30 s hoàn thành, phát một lần; luyện tập vẫn phát file gốc. 15/10: chỉ MỘT bài nghe phát tại một thời điểm (hết chồng tiếng khi chuyển bài); nút phát kiểu tờ đề có thanh tiến trình và thời gian | F11: 2 | G11: =IF(OR(D11="",F11=""),"chưa rõ",IF(F11>D11,"FRACILE",IF(D11>F11,"Vivoire","hoà"))) -> FRACILE | H11: Đang chạy | I11: migration 119, 121; lô 11 + 13; meta.audioLuyen giữ file gốc; đo silencedetect 3 khoảng 30 s
A12: B. Mô phỏng phòng thi | B12: Đồng hồ chạy tiếp khi đóng tab | C12: KHÔNG CÓ (chủ dự án xác nhận 14/10) | D12: 0 | E12: Có — mốc thời gian giữ ở máy chủ | F12: 2 | G12: =IF(OR(D12="",F12=""),"chưa rõ",IF(F12>D12,"FRACILE",IF(D12>F12,"Vivoire","hoà"))) -> FRACILE | H12: Đang chạy | I12: attempts.started_at; màn thi nằm ngoài vỏ app
A13: B. Mô phỏng phòng thi | B13: Đọc hiểu chia đôi màn hình, văn bản cuộn riêng | C13: KHÔNG CÓ (chủ dự án xác nhận 14/10) | D13: 0 | E13: Có | F13: 2 | G13: =IF(OR(D13="",F13=""),"chưa rõ",IF(F13>D13,"FRACILE",IF(D13>F13,"Vivoire","hoà"))) -> FRACILE | H13: Đang chạy | I13: Màn thi thử và PESelfEvaluation dùng cùng bố cục hai cột
... A17: C. Thư viện nội dung | B17: Số bài luyện | C17: 200 chép chính tả + 200 nghe điền từ + 400 bài luyện phát âm (công bố 10/10) | D17: 2 | E17: 110 bài, TẤT CẢ đã xuất bản (08/10): 90 bài luyện tập riêng + 20 bài thuộc đề thi thử, A1 → C1, trong đó các bài nghe giọng tổng hợp và 3 bài cắt từ Wikipédia parlée. 20/10: thêm 14 bài TRẢ PHÍ (A2, B1, B2, C1: đọc, viết, ngữ pháp, từ vựng, 2 bài nghe có audio; 94 câu), thư viện còn khoảng 80 bài. 20/10 (lần 2): thêm 10 bài đọc hiểu A2 MIỄN PHÍ (70 câu: email, thông báo, quảng cáo, công thức, blog…), đọc hiểu A2 trong thư viện từ 2 lên 12 bài | F17: 2 | G17: =IF(OR(D17="",F17=""),"chưa rõ",IF(F17>D17,"FRACILE",IF(D17>F17,"Vivoire","hoà"))) -> hoà | H17: Đang chạy | I17: select count(*) from exercises = 110, nháp = 0, đo 08/10/2026. Vẫn ít hơn 400 bài Vivoire công bố, nhưng vượt ngưỡng 60 để chấm 2
A18: C. Thư viện nội dung | B18: Số câu hỏi | C18: Không công bố | E18: 881 câu, 9 dạng: qcm (có thể kèm HÌNH), fill, conj, vf, tableau, ordre, tự luận, GHÉP CẶP, PHIẾU | F18: 2 | G18: =IF(OR(D18="",F18=""),"chưa rõ",IF(F18>D18,"FRACILE",IF(D18>F18,"Vivoire","hoà"))) -> chưa rõ | H18: Đang chạy | I18: select count(*) from questions = 881, đo 08/10/2026
A19: C. Thư viện nội dung | B19: Audio bản xứ | C19: Có (nêu rõ « audio bản xứ ») | D19: 2 | E19: 25 bài nghe, 196 câu (02/10): A1 4 bài/23 câu · A2 5/25 · B1 9/71 · B2 4/48 · C1 3/29. Phần lớn là GIỌNG TỔNG HỢP (OpenAI TTS, ghi rõ trong bài); 3 bài C1 người thật đọc (Wikipédia parlée, CC0/PD/GFDL, ghi nguồn); 3 bài cũ không rõ nguồn giọng. Bài B1/B2 mới dài 1'40–2'30, 12–14 câu/bài như đề thật. Chưa có audio người bản xứ thu riêng | F19: 1 | G19: =IF(OR(D19="",F19=""),"chưa rõ",IF(F19>D19,"FRACILE",IF(D19>F19,"Vivoire","hoà"))) -> Vivoire | H19: Đang chạy — 4 bài nghe B1 đã xuất bản; các bài khác đang nháp | I19: Edge Function tao-audio + kho nghe (114); docs/nghe/kich-ban-nghe.md liệt kê nguồn đã kiểm và đã loại (Audio-Lingua cấm đăng lại, RFI/TV5 có bản quyền)
A20: C. Thư viện nội dung | B20: Nhập đề hàng loạt | C20: KHÔNG CÓ (chủ dự án xác nhận 14/10) | D20: 0 | E20: Dán một khối JSON là xong cả bài 25 câu. KHÔNG đọc được .docx | F20: 2 | G20: =IF(OR(D20="",F20=""),"chưa rõ",IF(F20>D20,"FRACILE",IF(D20>F20,"Vivoire","hoà"))) -> FRACILE | H20: Đang chạy | I20: Builder.jsx — trình nhập JSON
A21: D. Công cụ học tập | B21: Flashcard — cơ chế | C21: Flashcard + 3 game mỗi ngày, « ôn từ đúng lúc sắp quên » | D21: 2 | E21: Bộ do GIÁO VIÊN soạn, lịch ôn SM-2, thẻ lật 3D. Giao diện làm lại 09/10: Leon phản ứng theo lần chấm, nút chấm có phím 1–4, phím cách để lật, âm thanh. Từ 10/10 có BỘ TRẢ PHÍ: học sinh thấy ổ khoá + giá, mua bằng chuyển khoản (tự mở khoá khi tiền về), VIP mở hết. 15/10: cuối buổi tổng kết thẻ sai, nút « Làm lại thẻ sai » / luyện lại cả bộ (không đổi lịch ôn) | F21: 2 | G21: =IF(OR(D21="",F21=""),"chưa rõ",IF(F21>D21,"FRACILE",IF(D21>F21,"Vivoire","hoà"))) -> hoà | H21: Đang chạy — chưa có giao dịch mua bộ thật | I21: LuyenBoThe.jsx, BoTheApp.jsx; migration 128 (co_quyen_bo, RLS thẻ theo quyền), 130 (mua_bo_the); webhook SePay nhận mã BO<4 ký tự>
A22: D. Công cụ học tập | B22: Flashcard — quy mô | C22: Không công bố số thẻ | E22: 12 bộ · 131 thẻ, cả 12 công khai (26/09), 3 bộ mỗi kỹ năng, mỗi thẻ có câu ví dụ. 15/10: thêm 9 bộ, 108 thẻ (Nghe, Viết, Nói mỗi kỹ năng 6 bộ) | F22: 2 | G22: =IF(OR(D22="",F22=""),"chưa rõ",IF(F22>D22,"FRACILE",IF(D22>F22,"Vivoire","hoà"))) -> chưa rõ | H22: Đang chạy — 12 công khai | I22: the_bo = 4, the_bo_the = 35; học sinh mở bằng tài khoản thật thấy đủ bốn bộ (21/09)
A23: D. Công cụ học tập | B23: Soạn thẻ hàng loạt | C23: KHÔNG CÓ (chủ dự án xác nhận 14/10) | D23: 0 | E23: Dán nhiều dòng « mặt trước | mặt sau | phiên âm »; dòng hỏng được gọi tên kèm số dòng | F23: 2 | G23: =IF(OR(D23="",F23=""),"chưa rõ",IF(F23>D23,"FRACILE",IF(D23>F23,"Vivoire","hoà"))) -> FRACILE | H23: Đang chạy | I23: shared/boTheGiaoVien.js bocDong(); chủ dự án tạo bộ thử qua giao diện 12/09
A24: D. Công cụ học tập | B24: Chuỗi ngày học | C24: Có, kèm nhiệm vụ và kim cương | D24: 2 | E24: Có — widget trang chủ: chuỗi + 7 ô trong tuần, tính ở MÁY CHỦ từ lượt nộp bài theo giờ Việt Nam (đổi đồng hồ máy không có tác dụng). 22/10: chuỗi tính MỌI hoạt động (bài tập, thi thử, Flashcard, Thách đấu, Lộ trình, Nghe & Nói, Học ngữ pháp), chỉ máy chủ ghi ngày học nên không tự đắp được; bù lịch sử: 12 học sinh có chuỗi (trước 8) | F24: 2 | G24: =IF(OR(D24="",F24=""),"chưa rõ",IF(F24>D24,"FRACILE",IF(D24>F24,"Vivoire","hoà"))) -> hoà | H24: Đang chạy | I24: migration 095/096; RPC get_student_streak — đo bằng claim giả: 3 ngày liên tiếp ra 3, ngày bỏ trống cắt chuỗi (25/09)
A25: D. Công cụ học tập | B25: Tìm kiếm bài tập / học sinh | C25: KHÔNG CÓ (chủ dự án xác nhận 14/10) | D25: 0 | E25: Ô tìm ở thanh trên, mở thẳng bài hoặc hồ sơ. Chạy bằng quyền người tìm nên học sinh không thấy hồ sơ người khác | F25: 2 | G25: =IF(OR(D25="",F25=""),"chưa rõ",IF(F25>D25,"FRACILE",IF(D25>F25,"Vivoire","hoà"))) -> FRACILE | H25: Đang chạy — chưa thử qua giao diện | I25: migration 097/098; RPC global_search (SECURITY INVOKER) — giáo viên tìm « ng »: 3 bài + 6 học sinh; học sinh: 3 bài + 0
A26: D. Công cụ học tập | B26: Trò chơi / thi đấu | C26: Đấu dịch thuật PvP trực tiếp | D26: 2 | E26: Game Lộ trình + Thách đấu bạn bè. Từ 10/10 thách đấu theo CHỦ ĐỀ (3 chủ đề từ vựng, 4 chủ đề ngữ pháp và diễn đạt): gộp thẻ mọi bộ cùng chủ đề, rút ngẫu nhiên 10 câu; phương án cùng DẠNG, ưu tiên cùng chủ đề, bỏ phần giải thích trong ngoặc; giáo viên soạn được 3 nghĩa sai cho từng thẻ. Giao diện đấu trường mới: đếm ngược 3-2-1, phím 1–4, hiệu ứng và âm thanh. 15/10: sau trận xem lại từng câu đúng/sai và làm lại câu sai (luyện tập, không đổi kết quả trận). 16/10: khung « Đang theo dõi » hiện số người theo dõi / đang theo dõi, danh sách cuộn trong khung. 18/10: Thách đấu chọn bạn cuộn ngang, chủ đề cuộn dọc có ô tìm (gõ không dấu) | F26: 2 | G26: =IF(OR(D26="",F26=""),"chưa rõ",IF(F26>D26,"FRACILE",IF(D26>F26,"Vivoire","hoà"))) -> hoà | H26: Đang chạy — trận theo chủ đề chưa chơi thật trên giao diện | I26: migration 127–129 (chu_de_the, the_bo.chu_de, the_bo_the.loai/nhieu, sach_pa). Thử trên DB: 7 chủ đề đều ra 10 câu, 0 dấu ngoặc
A27: D. Công cụ học tập | B27: XP (điểm kinh nghiệm) | C27: Có, kèm kim cương | D27: 2 | E27: Cộng ở MÁY CHỦ: nộp bài lần đầu (10 + điểm, từ 26/09) và qua màn Lộ trình lần đầu (5 XP, thử thách 15 XP, từ 29/09); có sổ cái; đổi XP lấy bài trả phí theo giá giáo viên đặt. Chưa bài nào đặt giá XP | F27: 2 | G27: =IF(OR(D27="",F27=""),"chưa rõ",IF(F27>D27,"FRACILE",IF(D27>F27,"Vivoire","hoà"))) -> hoà | H27: Đang chạy — chưa ai đổi qua giao diện | I27: migration 101–103; claim giả: nộp 2 lần chỉ cộng 1 lần, đổi 15 XP mở được bài, bấm lại không trừ thêm. 5 tài khoản được cộng bù (13–52 XP)
A28: D. Công cụ học tập | B28: Theo dõi bạn học | C28: Có (bạn bè, bảng xếp hạng) | D28: 2 | E28: Theo dõi một chiều bằng @username; thấy « hôm nay đã học chưa », bảng xếp hạng XP, và từ 08/10 TRẠNG THÁI ONLINE (chấm xanh, « online 12 phút trước ») của người mình theo dõi; có tùy chọn ẩn trạng thái. 19/10: mọi tài khoản tự có @username từ tên, tìm bạn theo tên không cần dấu, gợi ý theo dõi kèm lý do (theo dõi bạn, bạn chung, cùng trường, cùng trình độ), link kết bạn | F28: 2 | G28: =IF(OR(D28="",F28=""),"chưa rõ",IF(F28>D28,"FRACILE",IF(D28>F28,"Vivoire","hoà"))) -> hoà | H28: Đang chạy — 4 lượt theo dõi | I28: migration 123 (cột profiles.lan_cuoi_online thay blob mcf-presence); thử bằng claim giả: ẩn → người theo dõi không thấy
A29: D. Công cụ học tập | B29: Giờ học đo được | C29: KHÔNG CÓ (chủ dự án xác nhận 14/10) | D29: 0 | E29: Đo thật từ 27/09: thời gian từ lúc mở bài tới lúc nộp (kẹp 3 giờ), biểu đồ 7 ngày. Chỉ tính bài nộp từ 27/09 trở đi | F29: 2 | G29: =IF(OR(D29="",F29=""),"chưa rõ",IF(F29>D29,"FRACILE",IF(D29>F29,"Vivoire","hoà"))) -> FRACILE | H29: Đang chạy | I29: migration 106: attempts.giay_lam + RPC get_gio_hoc; không điền số ước lượng cho quá khứ
A30: D. Công cụ học tập | B30: Lộ trình học dạng game | C30: Lộ trình theo cấp độ | D30: 2 | E30: 16 chủ đề xã hội, 100 màn, 800 mục từ có loại từ; nhiễu cùng loại từ. Giao diện làm lại 09/10: khung đầu có Leon + thanh sao, đường tự vẽ, màn hiện tại có vòng sáng và Leon đứng cạnh; màn chơi có Leon phản ứng, pháo giấy, rung khi sai, âm thanh, phím 1–4. 15/10: nhạc nền kiểu EDM (build-up, drop) tổng hợp trong trình duyệt, bật/tắt bằng nút loa. 23/10: Lộ trình và Học ngữ pháp gộp thành một mục « Học tập » trên thanh bên, hai tab. 23/10 (tối): Lộ trình có CHƯƠNG: thêm chương 2 cho cả 16 chủ đề (160 màn B2, 1.280 từ và cụm nghị luận, không trùng chương 1), mở khi qua thử thách cuối chương 1; tổng 260 màn, 2.080 mục. Bản đồ có hoạ tiết, bảng tóm tắt chương, dải phản hồi mới | F30: 2 | G30: =IF(OR(D30="",F30=""),"chưa rõ",IF(F30>D30,"FRACILE",IF(D30>F30,"Vivoire","hoà"))) -> hoà | H30: Đang chạy | I30: LoTrinh.jsx, TroChoiMan.jsx, shared/amThanh.js (Web Audio, không file)
A31: E. Tài khoản giáo viên | B31: Kiểm soát ai được học bài nào | C31: KHÔNG CÓ (chủ dự án xác nhận 14/10) | D31: 0 | E31: Ba tầng cho bài tập (VIP 99.000 đ/30 ngày, trọn gói, từng bài) và từ 10/10 cho cả BỘ FLASHCARD: giáo viên đặt bộ trả phí + giá, cấp/thu quyền từng học sinh; học sinh tự mua bằng chuyển khoản | F31: 2 | G31: =IF(OR(D31="",F31=""),"chưa rõ",IF(F31>D31,"FRACILE",IF(D31>F31,"Vivoire","hoà"))) -> FRACILE | H31: Đang chạy | I31: QuyenBaiTap.jsx, QuanLyVip.jsx, SoanBoThe.jsx; migration 118, 122, 128, 130
A32: E. Tài khoản giáo viên | B32: Học sinh KHÔNG tự mở khoá được cho mình | C32: KHÔNG CÓ (chủ dự án xác nhận 14/10) | D32: 0 | E32: exercise_access chặn mọi lệnh ghi từ trình duyệt; phải qua Edge Function | F32: 2 | G32: =IF(OR(D32="",F32=""),"chưa rõ",IF(F32>D32,"FRACILE",IF(D32>F32,"Vivoire","hoà"))) -> FRACILE | H32: Đang chạy — GIỮ | I32: migration 001; grant-access giữ service_role
A33: E. Tài khoản giáo viên | B33: Soạn đề thi thử | C33: KHÔNG CÓ (chủ dự án xác nhận 14/10) | D33: 0 | E33: Có — ghép bài từ thư viện vào 4 phần, đặt phút và điểm từng phần. 19/10: soạn và sửa nội dung từng phần ngay trong đề (không chọn từ thư viện), chọn Đề thường / Đề VIP, nút « Xem như học sinh » mở đúng màn thi ở chế độ xem thử (không lưu, tắt ghi âm), soạn chủ đề bốc thăm cho phần Nói | F33: 2 | G33: =IF(OR(D33="",F33=""),"chưa rõ",IF(F33>D33,"FRACILE",IF(D33>F33,"Vivoire","hoà"))) -> FRACILE | H33: Đang chạy — GIỮ | I33: ExamComposer.jsx; /professeur/examens
A34: E. Tài khoản giáo viên | B34: Soạn bài và quản lý thư viện | C34: KHÔNG CÓ (chủ dự án xác nhận 14/10) | D34: 0 | E34: Có — Builder, thư mục, chuyển bài giữa Entraînement và Devoir. 19/10: trình soạn bài chia 4 phần đánh số (thông tin, đề bài và tài liệu, cài đặt, câu hỏi), thêm câu hỏi theo 3 nhóm có mô tả, tên dạng câu tiếng Việt, thanh lưu dính đáy | F34: 2 | G34: =IF(OR(D34="",F34=""),"chưa rõ",IF(F34>D34,"FRACILE",IF(D34>F34,"Vivoire","hoà"))) -> FRACILE | H34: Đang chạy — GIỮ | I34: Builder.jsx; exerciseStore.js
... A39: E. Tài khoản giáo viên | B39: Xem đăng ký tư vấn (leads) | C39: Có form thu thông tin | D39: 2 | E39: ĐÃ GỠ khỏi tài khoản giáo viên 07/10 theo chủ dự án; bảng leads còn nguyên | F39: 0 | G39: =IF(OR(D39="",F39=""),"chưa rõ",IF(F39>D39,"FRACILE",IF(D39>F39,"Vivoire","hoà"))) -> Vivoire | H39: Đã gỡ — có chủ đích | I39: Lấy lại XemLienHe.jsx từ git trước commit 35759f3
A40: E. Tài khoản giáo viên | B40: Số tài khoản đang có | C40: Không công bố | E40: 17 hồ sơ người dùng (gồm cả tài khoản thử) | F40: 1 | G40: =IF(OR(D40="",F40=""),"chưa rõ",IF(F40>D40,"FRACILE",IF(D40>F40,"Vivoire","hoà"))) -> chưa rõ | H40: Đang chạy | I40: select count(*) from profiles = 17, đo 06/10/2026
A41: E. Tài khoản giáo viên | B41: Giáo viên điều chỉnh lộ trình học | C41: KHÔNG CÓ (chủ dự án xác nhận 14/10) | D41: 0 | E41: ĐÃ GỠ màn giáo viên 07/10; lộ trình chạy theo cấu hình mặc định (bảng lo_trinh_cau_hinh còn nguyên) | F41: 0 | G41: =IF(OR(D41="",F41=""),"chưa rõ",IF(F41>D41,"FRACILE",IF(D41>F41,"Vivoire","hoà"))) -> hoà | H41: Đã gỡ — có chủ đích | I41: Lấy lại LoTrinhGiaoVien.jsx từ git
A42: E. Tài khoản giáo viên | B42: Thống kê lớp + xuất Google Sheets | C42: KHÔNG CÓ (chủ dự án xác nhận 14/10) | D42: 0 | E42: Trang Thống kê: tổng quan 7 ngày (học sinh hoạt động, thời gian học, điểm TB, tỷ lệ hoàn thành — đều so tuần trước), biểu đồ hoạt động, radar kỹ năng, bảng từng học sinh. Nút « Đồng bộ Google Sheets » để máy chủ tự ghi 3 trang tính (30 ngày) vào bảng tính cố định, có biên nhận số dòng | F42: 2 | G42: =IF(OR(D42="",F42=""),"chưa rõ",IF(F42>D42,"FRACILE",IF(D42>F42,"Vivoire","hoà"))) -> FRACILE | H42: Đã dựng 02/10 — chờ chủ dự án nối Google (5 phút, một lần) | I42: Edge Function dong-bo-sheets (chỉ giáo viên, số liệu đọc ở máy chủ) + docs/google-sheets/Code.gs. Thử: chưa cấu hình → CHUA_CAU_HINH_SHEETS; CORS đạt. Trang /bao-mat đã ghi Google là bên nhận dữ liệu
A43: E. Tài khoản giáo viên | B43: Duyệt và xuất bản bài soạn sẵn | C43: KHÔNG CÓ (chủ dự án xác nhận 14/10) | D43: 0 | E43: Có từ 02/10 (/professeur/duyet-nhap): đọc trọn bài (ngữ liệu, đáp án, lời giải) rồi xuất bản một cú bấm, máy chủ trả biên nhận | F43: 2 | G43: =IF(OR(D43="",F43=""),"chưa rõ",IF(F43>D43,"FRACILE",IF(D43>F43,"Vivoire","hoà"))) -> FRACILE | H43: Đang chạy — chưa xuất bản bài nào qua trang này | I43: RPC xuat_ban_nhap (113): một lệnh UPDATE, không xoá-chèn lại câu hỏi
A44: F. Nền tảng & phân phối | B44: Web | C44: Có | D44: 2 | E44: Có. Gửi link hiện ảnh xem trước (og:image 1200×630, banner FRACILE cùng Leon) trên Facebook, Messenger, Zalo, iMessage. Tên miền riêng www.fracile.vn (fracile.vn, fracile.cloud, fracile.vercel.app chuyển hướng về). Trang chủ dựng sẵn + khai báo thương hiệu (JSON-LD tổ chức, website, tên khác) + llms.txt cho AI; đã khai Google Search Console (trang chủ đã lập chỉ mục) và Bing Webmaster | F44: 2 | G44: =IF(OR(D44="",F44=""),"chưa rõ",IF(F44>D44,"FRACILE",IF(D44>F44,"Vivoire","hoà"))) -> hoà | H44: Đang chạy | I44: fracile.vercel.app / www.fracile.vn
A45: F. Nền tảng & phân phối | B45: Tiến độ đồng bộ nhiều thiết bị | C45: Có | D45: 2 | E45: Có (dữ liệu ở máy chủ), nhưng chỉ một nền tảng nên chưa thành lợi thế | F45: 1 | G45: =IF(OR(D45="",F45=""),"chưa rõ",IF(F45>D45,"FRACILE",IF(D45>F45,"Vivoire","hoà"))) -> Vivoire | H45: Đang chạy
A46: F. Nền tảng & phân phối | B46: Ngôn ngữ giao diện | C46: Việt (giao diện) + Pháp (nội dung) | D46: 1 | E46: Việt · Pháp · Anh, LÀM LẠI 08/10: ~650 chuỗi viết cứng trong ~40 màn (thi thử, chấm bài, luyện tập, giáo viên, trang giới thiệu, pháp lý) đưa qua bộ dịch, không còn lẫn ngôn ngữ. Nội dung học (đề tiếng Pháp) giữ nguyên. 18/10: trình độ và mục tiêu trong hồ sơ hiện nhãn tiếng Việt | F46: 2 | G46: =IF(OR(D46="",F46=""),"chưa rõ",IF(F46>D46,"FRACILE",IF(D46>F46,"Vivoire","hoà"))) -> FRACILE | H46: Đang chạy — còn nút định dạng trong trình soạn của giáo viên | I46: Hàm tr(vi, fr, en) trong shared/i18n.jsx; công cụ scripts/i18n/trich.cjs + ap.cjs; quy tắc 6b trong CLAUDE.md. Xem trước ở /preview.html bằng fr/en
A47: F. Nền tảng & phân phối | B47: Thanh toán | C47: Không có — FAQ 10/10: « mọi tính năng học đều miễn phí »; có trang « Ủng hộ » | E47: Webhook SePay đã ghim công thức ký; mua bài lẻ, gói VIP và (từ 10/10) bộ Flashcard trả phí qua cùng một mã nội dung chuyển khoản. 20/10: bảng giá chốt: VIP tháng 99.000đ, bài luyện trả phí 19.000đ/bài (hoặc đổi 190 XP), đề thi thử lẻ 39.000đ; VIP mở mọi bài trả phí | F47: 2 | G47: =IF(OR(D47="",F47=""),"chưa rõ",IF(F47>D47,"FRACILE",IF(D47>F47,"Vivoire","hoà"))) -> chưa rõ | H47: Đang chạy — mua bộ Flashcard chưa có giao dịch thật | I47: check:hmac 45 ca; mua_bo_the thử trên DB: thiếu tiền bị từ chối, giao dịch gửi lại không ghi hai lần
...

Sheet Tài khoản giáo viên
A1: TÀI KHOẢN GIÁO VIÊN — giữ để KIỂM SOÁT, không để CHẤM BÀI
A2: Quyết định của chủ dự án ngày 09/09/2026: giữ tài khoản giáo viên để quản lý số lượng học sinh và quyền truy cập; bỏ hoàn toàn việc giáo viên chấm bài. Học sinh tự chấm theo grille DELF; AI gợi ý chấm đã dựng nhưng chưa bật (thiếu khoá API).
A5: Quyền / màn hình | B5: Đường dẫn | C5: Quyết định | D5: Tình trạng mã nguồn HÔM NAY | E5: Ghi chú
A6: Bật/tắt quyền học từng bài cho một học sinh | B6: AccessPanel (trong dashboard) | C6: GIỮ — DỰNG LẠI | D6: Đang chạy — giao diện mới 08/10 | E6: QuyenBaiTap.jsx: theo bài / theo học sinh, cấp theo nhóm. Quyền học sinh tự mua không gỡ được.
A7: Bật/tắt trọn gói cho một học sinh | B7: AccessPanel | C7: GIỮ | D7: Đang chạy | E7: profiles.has_premium_access — mở cả những bài chưa tồn tại lúc bật.
A8: Soạn / sửa / xoá bài trong thư viện | B8: /professeur/dashboard → Builder | C8: GIỮ | D8: Đang chạy — sửa lỗi lưu 26/09 | E8: LƯU BÀI HỎNG 24–26/09 (upsert từ client bị từ chối vì cột đáp án bị khoá). Nay ghi qua RPC luu_cau_hoi (104), một transaction; đã thử bằng claim giả, CHƯA thử lại qua giao diện. Form đã dịch ba thứ tiếng.
A9: Soạn đề thi thử | B9: /professeur/examens | C9: GIỮ | D9: Đang chạy | E9: Ghép bài vào 4 phần CO/CE/PE/PO, đặt phút và điểm từng phần.
A10: Soạn thang chấm riêng cho một đề | B10: /professeur/grille | C10: GIỮ | D10: Đang chạy | E10: CÀNG quan trọng khi học sinh tự chấm — thang là thứ duy nhất hướng dẫn họ.
A11: Viết lời giải thích, xếp theo số học sinh sai | B11: /professeur/loi-giai | C11: ĐÃ GỠ | D11: Không còn trong menu | E11: Gỡ 07/10: AI chấm và giải thích thay. Dữ liệu lời giải giữ nguyên.
A12: Đặt neo đáp án vào ngữ liệu | B12: /professeur/neo | C12: GIỮ — DỰNG LẠI | D12: Đang chạy — giao diện mới 07/10 | E12: Lưới bài + màn 3 cột (danh sách câu · đoạn văn · neo và xem trước).
A13: Sổ tay / mẹo | B13: /professeur/carnet | C13: ĐÃ GỠ | D13: Không còn trong menu | E13: Gỡ 07/10 theo chủ dự án; mẹo cũ vẫn hiện cho học sinh.
A14: Soạn Flashcard | B14: /professeur/bo-the | C14: GIỮ — DỰNG LẠI | D14: Đang chạy — giao diện mới 07/10 | E14: Lưới bộ lọc theo kỹ năng; thêm từng thẻ hoặc dán nhiều dòng; sửa thẻ tại chỗ.
A15: Xem câu hỏi / đăng ký tư vấn | B15: /professeur/lien-he | C15: ĐÃ GỠ | D15: Không còn trong menu | E15: Gỡ 07/10; bảng leads còn nguyên.
A16: Nghe bản ghi âm bài nói của học sinh | B16: /professeur/oral | C16: ĐÃ GỠ | D16: Không còn trong mã | E16: Gỡ 23/09 theo quyết định chủ dự án. Học sinh vẫn ghi âm để tự nghe lại.
... A25: Thư viện luyện tập (mục riêng) | B25: /professeur/exercices | C25: ĐÃ ĐỔI CHỮ | D25: Đang chạy | E25: Gộp thành tab thứ hai trong « Bài tập » 07/10.
A28: MỘT CÂU PHẢI NÓI THẲNG
A29: Bỏ giáo viên chấm bài chưa tự động thành « AI chấm ». Chấm AI đã DỰNG (Edge Function cham-pe) nhưng CHƯA CHẠY: thiếu khoá ANTHROPIC_API_KEY, gọi vào nhận 503 CHUA_CAU_HINH_KHOA, và bảng gợi ý có 0 dòng (đo 21/09). Nên kể từ 09/09, bài viết của học sinh chỉ còn MỘT đường: tự chấm theo grille DELF. Khoảng trống này kéo dài đúng bằng thời gian tới khi đặt khoá — việc số 1 trong sheet « Việc cần làm ». Và 8 bài tự luận đã nộp chưa có điểm nào — không điểm giáo viên, không điểm tự chấm. Chưa ai báo gì cho người viết chúng.

Sheet Số liệu đo được
A1: SỐ LIỆU ĐO THẬT — không con số nào ở đây là ước lượng
A3: Chỉ số | B3: Giá trị | C3: Cách đo | D3: Ngày đo
A4: Bài tập | B4: 161 | C4: select count(*) from exercises — 68 thư viện luyện tập + 93 kho thi thử (14/10) | D4: 13/10/2026
A5: Câu hỏi | B5: 943 | C5: select count(*) from questions | D5: 13/10/2026
A6: Câu có lời giải thích | B6: 704 | C6: questions where explanation is not null | D6: 08/10/2026
A7: Câu có neo ngữ liệu | B7: 22 | C7: questions where evidence is not null | D7: 08/10/2026
A8: Đề thi thử | B8: 13 | C8: select count(*) from exams where is_published — 14/10 | D8: 13/10/2026
A9: Lượt làm bài đã chấm | B9: 109 | C9: attempts where finished_at is not null | D9: 13/10/2026
A10: Bộ Flashcard (cả 12 công khai) | B10: 12 | C10: select count(*) from the_bo where cong_khai | D10: 26/09/2026
A11: Thẻ trong các bộ | B11: 131 | C11: select count(*) from the_bo_the | D11: 26/09/2026
A12: Thẻ trong bảng cards | B12: 18 | C12: select count(*) from cards — 36 thẻ đi theo hai tài khoản thử đã xoá | D12: 24/09/2026
A13: Lượt trả lời đã ghi | B13: 57 | C13: select count(*) from answers — 50 đi theo tài khoản thử, ~70 mất vì lỗi lưu bài (đã sửa) | D13: 24/09/2026
A14: Tài khoản | B14: 21 | C14: select count(*) from profiles | D14: 13/10/2026
A15: Lượt đổi XP lấy bài | B15: 1 | C15: exercise_access where status='XP' | D15: 08/10/2026
... A23: Câu luyện Nghe & Nói | B23: 600 | C23: select count(*) from cau_luyen — 200 chép chính tả + 200 điền từ + 200 phát âm | D23: 13/10/2026
A25: Tỷ lệ câu có lời giải | B25: =B6/B5 -> 0.79909194 | C25: = câu có lời giải ÷ tổng câu hỏi
A26: Số câu còn thiếu lời giải | B26: =B5-B6 -> 177 | C26: Trong đó 25 câu vf vốn đã có justification sẵn
A29: VIVOIRE — họ công bố, tôi KHÔNG kiểm chứng được
A30: Chỉ số | B30: Giá trị | C30: Nguồn | D30: Độ tin
A31: Bài chép chính tả | B31: 200 | C31: trang chủ | D31: họ tự công bố
A32: Bài nghe điền từ | B32: 200 | C32: trang chủ | D32: họ tự công bố
A33: Cấp độ | B33: A1 → C2 | C33: trang chủ | D33: họ tự công bố
A34: Học viên một lớp | B34: 28 | C34: ảnh minh hoạ trên trang chủ | D34: ẢNH MINH HOẠ — không phải số thật
A35: Phản hồi AI bài nói | B35: Phát âm 82% · Trôi chảy 76% | C35: ảnh minh hoạ | D35: ẢNH MINH HOẠ — không phải số thật
A36: Khối đếm trên trang chủ | B36: hiện 0 | C36: đọc trực tiếp DOM 09/09 | D36: gần như chắc chắn là hiệu ứng đếm chưa chạy

Sheet Việc cần làm
A1: RÚT RA TỪ BẢNG — xếp theo thứ tự nên làm
A3: # | B3: Việc | C3: Vì sao đứng ở vị trí này | D3: Chạm vào đâu | E3: Công sức
A4: 1 | B4: Thi thử một đề có bật phần nói rồi tự chấm | C4: Phần nói chấm điểm, bốc thăm, chuẩn bị và AI gợi ý mới dựng 12–13/10; database 13/10: 0 bài nói đã tự chấm. | D4: Thi thử → bật « Làm cả phần thi nói » → Kết quả thi → « Tự chấm phần nói » | E4: 40 phút
